Workbook

Sheet Income Statement
A1: Ticker | B1: FY | C1: Total Revenue | D1: Cost of Revenue | E1: Gross Profit | F1: SG&A | G1: R&D | H1: D&A | I1: Unusual Expense | J1: Other Operating Expenses | K1: Total Operating Expense | L1: Operating Income | M1: Interest Inc.(Exp) | N1: Gain (Loss) on Sale of Assets | O1: Other | P1: Net Income Before Taxes | Q1: Provision for Income Taxes | R1: Net Income | S1: Basic EPS Excluding Extraordinary Items | T1: Basic EPS Including Extraordinary Items | U1: Normalized Basic EPS | V1: Basic Weighted Average Shares | W1: Diluted EPS Excluding ExtraOrd Items | X1: Diluted EPS Including ExtraOrd Items | Y1: Normalized Diluted EPS | Z1: Diluted Weighted Average Shares | AA1: Dividends Per Share | AB1: Number of Employees
A2: AMZN | B2: 46022 | C2: 716924 | D2: 356414 | E2: 360510 | F2: 167375 | G2: 108521 | H2: 817 | I2: 4900 | J2: -1078 | K2: 636949 | L2: 79975 | M2: 9165 | O2: 8171 | P2: 97311 | Q2: 19087 | R2: 77670 | S2: 7.29 | T2: 7.29 | U2: 7.96 | V2: 10656 | W2: 7.17 | X2: 7.17 | Y2: 7.83 | Z2: 10827 | AB2: 1576000
A3: AMZN | B3: 45657 | C3: 637959 | D3: 326288 | E3: 311671 | F3: 153771 | G3: 88544 | H3: 838 | I3: -75 | K3: 569366 | L3: 68593 | M3: 585 | O3: -564 | P3: 68614 | Q3: 9265 | R3: 59248 | S3: 5.66 | T3: 5.66 | U3: 5.65 | V3: 10473 | W3: 5.53 | X3: 5.53 | Y3: 5.52 | Z3: 10721 | AB3: 1556000
A4: AMZN | B4: 45291 | C4: 574785 | D4: 304739 | E4: 270046 | F4: 146805 | G4: 85622 | H4: 706 | I4: 61 | K4: 537933 | L4: 36852 | M4: 816 | O4: -111 | P4: 37557 | Q4: 7120 | R4: 30425 | S4: 2.95 | T4: 2.95 | U4: 2.96 | V4: 10304 | W4: 2.9 | X4: 2.9 | Y4: 2.9 | Z4: 10492 | AB4: 1525000
A5: AMZN | B5: 44926 | C5: 513983 | D5: 288831 | E5: 225152 | F5: 138428 | G5: 73213 | H5: 604 | I5: 1100 | J5: -441 | K5: 501735 | L5: 12248 | M5: -15588 | O5: -2596 | P5: -5936 | Q5: -3217 | R5: -2722 | S5: -0.27 | T5: -0.27 | U5: -0.2 | V5: 10189 | W5: -0.27 | X5: -0.27 | Y5: -0.2 | Z5: 10189 | AB5: 1541000
A6: AMZN | B6: 44561 | C6: 469822 | D6: 272344 | E6: 197478 | F6: 116485 | G6: 56052 | H6: 512 | J6: -450 | K6: 444943 | L6: 24879 | M6: 10110 | O6: 3162 | P6: 38151 | Q6: 4791 | R6: 33364 | S6: 3.3 | T6: 3.3 | U6: 3.3 | V6: 10120 | W6: 3.24 | X6: 3.24 | Y6: 3.24 | Z6: 10300 | AB6: 1608000
A7: AMZN | B7: 44196 | C7: 386064 | D7: 233307 | E7: 152757 | F7: 87193 | G7: 42740 | H7: 509 | J7: -584 | K7: 363165 | L7: 22899 | M7: -224 | O7: 1503 | P7: 24178 | Q7: 2863 | R7: 21331 | S7: 2.13 | T7: 2.13 | U7: 3.15 | V7: 10000 | W7: 2.09 | X7: 2.09 | Y7: 3.09 | Z7: 10200 | AB7: 1298000
A8: AMZN | B8: 43830 | C8: 280522 | D8: 165536 | E8: 114986 | F8: 64313 | G8: 35931 | H8: 565 | J8: -364 | K8: 265981 | L8: 14541 | M8: -557 | O8: -8 | P8: 13976 | Q8: 2374 | R8: 11588 | S8: 1.17 | T8: 1.17 | U8: 1.17 | V8: 9880 | W8: 1.15 | X8: 1.15 | Y8: 1.15 | Z8: 10080 | AB8: 798000
A9: AMZN | B9: 43465 | C9: 232887 | D9: 139156 | E9: 93731 | F9: 52177 | G9: 28837 | H9: 475 | J9: -179 | K9: 220466 | L9: 12421 | M9: -977 | O9: -183 | P9: 11261 | Q9: 1354 | R9: 10073 | S9: 1.02 | T9: 1.03 | U9: 1.02 | V9: 9740 | W9: 0.99 | X9: 1.01 | Y9: 0.99 | Z9: 10000 | AB9: 647500
A10: AMZN | B10: 43100 | C10: 177866 | D10: 111934 | E10: 65932 | F10: 38992 | G10: 22620 | H10: 366 | J10: -152 | K10: 173760 | L10: 4106 | M10: -406 | O10: 106 | P10: 3806 | Q10: 1558 | R10: 3033 | S10: 0.23 | T10: 0.32 | U10: 0.23 | V10: 9600 | W10: 0.23 | X10: 0.31 | Y10: 0.23 | Z10: 9860 | AB10: 566000
A11: AMZN | B11: 42735 | C11: 135987 | D11: 88265 | E11: 47722 | F11: 27284 | G11: 16085 | H11: 287 | J11: -120 | K11: 131801 | L11: 4186 | M11: -371 | O11: 77 | P11: 3892 | Q11: 1425 | R11: 2371 | S11: 0.25 | T11: 0.25 | U11: 0.25 | V11: 9480 | W11: 0.24 | X11: 0.24 | Y11: 0.24 | Z11: 9680 | AA11: 0 | AB11: 341400
A12: AMZN | B12: 42369 | C12: 107006 | D12: 71651 | E12: 35355 | F12: 20411 | G12: 12540 | H12: 228 | J12: -57 | K12: 104773 | L12: 2233 | M12: -680 | O12: 15 | P12: 1568 | Q12: 950 | R12: 596 | S12: 0.06 | T12: 0.06 | U12: 0.06 | V12: 9340 | W12: 0.06 | X12: 0.06 | Y12: 0.06 | Z12: 9540 | AB12: 230800
A13: AMZN | B13: 42004 | C13: 88988 | D13: 62752 | E13: 26236 | F13: 16650 | G13: 9275 | H13: 181 | J13: -48 | K13: 88810 | L13: 178 | M13: -295 | O13: 6 | P13: -111 | Q13: 167 | R13: -241 | S13: -0.03 | T13: -0.03 | U13: -0.03 | V13: 9240 | W13: -0.03 | X13: -0.03 | Y13: -0.03 | Z13: 9240 | AB13: 154100
A14: AMZN | B14: 41639 | C14: 74452 | D14: 54181 | E14: 20271 | F14: 12847 | G14: 6565 | H14: 168 | J14: -54 | K14: 73707 | L14: 745 | M14: -241 | O14: 2 | P14: 506 | Q14: 161 | R14: 274 | S14: 0.03 | T14: 0.03 | U14: 0.03 | V14: 9140 | W14: 0.03 | X14: 0.03 | Y14: 0.03 | Z14: 9300 | AA14: 0 | AB14: 117300
A15: AMZN | B15: 41274 | C15: 61093 | D15: 45971 | E15: 15122 | F15: 9723 | G15: 4564 | J15: 159 | K15: 60417 | L15: 676 | M15: -137 | O15: 5 | P15: 544 | Q15: 428 | R15: -39 | S15: 0 | T15: 0 | U15: 0 | V15: 9060 | W15: 0 | X15: 0 | Y15: 0 | Z15: 9060 | AA15: 0 | AB15: 88400
A16: AMZN | B16: 40908 | C16: 48077 | D16: 37288 | E16: 10789 | F16: 6864 | G16: 2909 | J16: 154 | K16: 47215 | L16: 862 | M16: 64 | O16: 8 | P16: 934 | Q16: 291 | R16: 631 | S16: 0.07 | T16: 0.07 | U16: 0.07 | V16: 9060 | W16: 0.07 | X16: 0.07 | Y16: 0.07 | Z16: 9220 | AA16: 0 | AB16: 56200
A17: AMZN | B17: 40543 | C17: 34204 | D17: 26561 | E17: 7643 | F17: 4397 | G17: 1734 | J17: 106 | K17: 32798 | L17: 1406 | M17: 88 | O17: 3 | P17: 1497 | Q17: 352 | R17: 1152 | S17: 0.13 | T17: 0.13 | U17: 0.13 | V17: 8940 | W17: 0.13 | X17: 0.13 | Y17: 0.13 | Z17: 9120 | AA17: 0 | AB17: 33700
A18: AMZN | B18: 40178 | C18: 24509 | D18: 18978 | E18: 5531 | F18: 3060 | G18: 1240 | J18: 102 | K18: 23380 | L18: 1129 | M18: 33 | O18: -1 | P18: 1161 | Q18: 253 | R18: 902 | S18: 0.1 | T18: 0.1 | U18: 0.1 | V18: 8660 | W18: 0.1 | X18: 0.1 | Y18: 0.1 | Z18: 8840 | AA18: 0 | AB18: 24300
A19: AMZN | B19: 39813 | C19: 19166 | D19: 14896 | E19: 4270 | F19: 2419 | G19: 1033 | J19: -24 | K19: 18324 | L19: 842 | M19: 50 | O19: 9 | P19: 901 | Q19: 247 | R19: 645 | S19: 0.08 | T19: 0.08 | U19: 0.08 | V19: 8460 | W19: 0.07 | X19: 0.07 | Y19: 0.07 | Z19: 8640 | AA19: 0 | AB19: 20700
A20: AMZN | B20: 39447 | C20: 14835 | D20: 11482 | E20: 3353 | F20: 1871 | G20: 818 | J20: 9 | K20: 14180 | L20: 655 | M20: 12 | O20: -7 | P20: 660 | Q20: 184 | R20: 476 | S20: 0.06 | T20: 0.06 | U20: 0.06 | V20: 8260 | W20: 0.06 | X20: 0.06 | Y20: 0.06 | Z20: 8480 | AA20: 0 | AB20: 17000
A21: AMZN | B21: 39082 | C21: 10711 | D21: 8255 | E21: 2456 | F21: 1395 | G21: 662 | J21: 10 | K21: 10322 | L21: 389 | M21: -6 | O21: -6 | P21: 377 | Q21: 187 | R21: 190 | S21: 0.02 | T21: 0.02 | U21: 0.02 | V21: 8320 | W21: 0.02 | X21: 0.02 | Y21: 0.02 | Z21: 8480 | AA21: 0 | AB21: 13900
A22: MSFT | B22: 46022 | C22: 281724 | D22: 87831 | E22: 193893 | F22: 32877 | G22: 32488 | I22: 943 | K22: 154139 | L22: 127585 | M22: 767 | O22: -4725 | P22: 123627 | Q22: 21795 | R22: 101832 | S22: 13.7 | T22: 13.7 | U22: 13.8 | V22: 7433 | W22: 13.64 | X22: 13.64 | Y22: 13.75 | Z22: 7465 | AA22: 3.32 | AB22: 228000
A23: MSFT | B23: 45657 | C23: 245122 | D23: 74114 | E23: 171008 | F23: 32065 | G23: 29510 | I23: 206 | K23: 135895 | L23: 109227 | M23: -121 | O23: -1319 | P23: 107787 | Q23: 19651 | R23: 88136 | S23: 11.86 | T23: 11.86 | U23: 11.88 | V23: 7431 | W23: 11.8 | X23: 11.8 | Y23: 11.82 | Z23: 7469 | AA23: 3 | AB23: 228000
A24: MSFT | B24: 45291 | C24: 211915 | D24: 65863 | E24: 146052 | F24: 29163 | G24: 27195 | I24: 1201 | K24: 123422 | L24: 88493 | M24: 1041 | O24: -223 | P24: 89311 | Q24: 16950 | R24: 72361 | S24: 9.72 | T24: 9.72 | U24: 9.85 | V24: 7446 | W24: 9.68 | X24: 9.68 | Y24: 9.81 | Z24: 7472 | AA24: 2.72 | AB24: 221000
A25: MSFT | B25: 44926 | C25: 198270 | D25: 62650 | E25: 135620 | F25: 27725 | G25: 24512 | I25: 101 | K25: 114988 | L25: 83282 | M25: 466 | O25: -32 | P25: 83716 | Q25: 10978 | R25: 72738 | S25: 9.7 | T25: 9.7 | U25: 9.72 | V25: 7496 | W25: 9.65 | X25: 9.65 | Y25: 9.66 | Z25: 7540 | AA25: 2.42 | AB25: 221000
A26: MSFT | B26: 44561 | C26: 168088 | D26: 52232 | E26: 115856 | F26: 25224 | G26: 20716 | I26: 13 | K26: 98185 | L26: 69903 | M26: 1101 | O26: 98 | P26: 71102 | Q26: 9831 | R26: 61271 | S26: 8.12 | T26: 8.12 | U26: 8.12 | V26: 7547 | W26: 8.05 | X26: 8.05 | Y26: 8.05 | Z26: 7608 | AA26: 2.24 | AB26: 181000
A27: MSFT | B27: 44196 | C27: 143015 | D27: 46078 | E27: 96937 | F27: 24709 | G27: 19269 | I27: 133 | K27: 90189 | L27: 52826 | M27: 250 | O27: -40 | P27: 53036 | Q27: 8755 | R27: 44281 | S27: 5.82 | T27: 5.82 | U27: 5.85 | V27: 7610 | W27: 5.76 | X27: 5.76 | Y27: 5.8 | Z27: 7683 | AA27: 1.53 | AB27: 163000
A28: MSFT | B28: 43830 | C28: 125843 | D28: 42910 | E28: 82933 | F28: 23098 | G28: 16876 | I28: 26 | K28: 82910 | L28: 42933 | M28: 812 | O28: -57 | P28: 43688 | Q28: 4291 | R28: 39240 | S28: 5.13 | T28: 5.11 | U28: 5.14 | V28: 7673 | W28: 5.08 | X28: 5.06 | Y28: 5.08 | Z28: 7753 | AA28: 1.8 | AB28: 144000
A29: MSFT | B29: 43465 | C29: 110360 | D29: 38353 | E29: 72007 | F29: 22223 | G29: 14726 | I29: 47 | K29: 75349 | L29: 35011 | M29: 1522 | O29: -59 | P29: 36474 | Q29: 6203 | R29: 16571 | S29: 3.93 | T29: 2.15 | U29: 3.94 | V29: 7700 | W29: 3.88 | X29: 2.13 | Y29: 3.89 | Z29: 7794 | AA29: 1.65 | AB29: 131000
A30: MSFT | B30: 43100 | C30: 96571 | D30: 34261 | E30: 62310 | F30: 18648 | G30: 12292 | I30: 2400 | K30: 67601 | L30: 28970 | M30: 1182 | O30: -251 | P30: 29901 | Q30: 4412 | R30: 25489 | S30: 3.29 | T30: 3.29 | U30: 3.66 | V30: 7746 | W30: 3.25 | X30: 3.25 | Y30: 3.62 | Z30: 7832 | AA30: 1.53
A31: MSFT | B31: 42735 | C31: 91154 | D31: 32780 | E31: 58374 | F31: 19198 | G31: 11988 | I31: 1432 | K31: 65398 | L31: 25756 | M31: 78 | O31: -195 | P31: 25639 | Q31: 5100 | R31: 20539 | S31: 2.59 | T31: 2.59 | U31: 2.74 | V31: 7925 | W31: 2.56 | X31: 2.56 | Y31: 2.71 | Z31: 8013 | AA31: 1.39
A32: MSFT | B32: 42369 | C32: 93580 | D32: 33038 | E32: 60542 | F32: 20324 | G32: 12046 | I32: 10194 | K32: 75602 | L32: 17978 | M32: 796 | O32: -267 | P32: 18507 | Q32: 6314 | R32: 12193 | S32: 1.49 | T32: 1.49 | U32: 2.31 | V32: 8177 | W32: 1.48 | X32: 1.48 | Y32: 2.29 | Z32: 8254 | AA32: 1.21 | AB32: 118000
A33: MSFT | B33: 42004 | C33: 86833 | D33: 26934 | E33: 59899 | F33: 20632 | G33: 11381 | I33: 233 | K33: 59180 | L33: 27653 | M33: 336 | O33: -169 | P33: 27820 | Q33: 5746 | R33: 22074 | S33: 2.66 | T33: 2.66 | U33: 2.68 | V33: 8299 | W33: 2.63 | X33: 2.63 | Y33: 2.65 | Z33: 8399 | AA33: 1.07 | AB33: 128000
A34: MSFT | B34: 41639 | C34: 77849 | D34: 20249 | E34: 57600 | F34: 20425 | G34: 10411 | I34: 208 | K34: 51293 | L34: 26556 | M34: 302 | O34: 194 | P34: 27052 | Q34: 5189 | R34: 21863 | S34: 2.61 | T34: 2.61 | U34: 2.63 | V34: 8375 | W34: 2.58 | X34: 2.58 | Y34: 2.6 | Z34: 8470 | AA34: 0.89 | AB34: 99000
A35: MSFT | B35: 41274 | C35: 73723 | D35: 17530 | E35: 56193 | F35: 18426 | G35: 9811 | I35: 6193 | K35: 51960 | L35: 21763 | M35: 205 | O35: 299 | P35: 22267 | Q35: 5289 | R35: 16978 | S35: 2.02 | T35: 2.02 | U35: 2.58 | V35: 8396 | W35: 2 | X35: 2 | Y35: 2.55 | Z35: 8506 | AA35: 0.8 | AB35: 94000
A36: MSFT | B36: 40908 | C36: 69943 | D36: 15577 | E36: 54366 | F36: 18162 | G36: 9043 | I36: 0 | K36: 42782 | L36: 27161 | M36: 861 | O36: 49 | P36: 28071 | Q36: 4921 | R36: 23150 | S36: 2.73 | T36: 2.73 | U36: 2.73 | V36: 8490 | W36: 2.69 | X36: 2.69 | Y36: 2.69 | Z36: 8593 | AA36: 0.64 | AB36: 90000
A37: MSFT | B37: 40543 | C37: 62484 | D37: 12395 | E37: 50089 | F37: 17218 | G37: 8714 | I37: 59 | K37: 38386 | L37: 24098 | M37: 832 | O37: 83 | P37: 25013 | Q37: 6253 | R37: 18760 | S37: 2.13 | T37: 2.13 | U37: 2.14 | V37: 8813 | W37: 2.1 | X37: 2.1 | Y37: 2.12 | Z37: 8927 | AA37: 0.52 | AB37: 89000
A38: MSFT | B38: 40178 | C38: 58437 | D38: 12155 | E38: 46282 | F38: 16579 | G38: 9010 | I38: -532 | K38: 37212 | L38: 21225 | M38: -1348 | O38: -56 | P38: 19821 | Q38: 5252 | R38: 14569 | S38: 1.63 | T38: 1.63 | U38: 1.59 | V38: 8945 | W38: 1.62 | X38: 1.62 | Y38: 1.58 | Z38: 8996 | AA38: 0.52 | AB38: 93000
A39: MSFT | B39: 39813 | C39: 60420 | D39: 11598 | E39: 48822 | F39: 16366 | G39: 8164 | I39: 1800 | K39: 37928 | L39: 22492 | M39: 1772 | O39: -450 | P39: 23814 | Q39: 6133 | R39: 17681 | S39: 1.9 | T39: 1.9 | U39: 2.04 | V39: 9328 | W39: 1.87 | X39: 1.87 | Y39: 2.01 | Z39: 9470 | AA39: 0.44 | AB39: 91000
A40: MSFT | B40: 39447 | C40: 51122 | D40: 10693 | E40: 40429 | F40: 14273 | G40: 7121 | I40: 511 | K40: 32598 | L40: 18524 | M40: 1636 | O40: -59 | P40: 20101 | Q40: 6036 | R40: 14065 | S40: 1.44 | T40: 1.44 | U40: 1.48 | V40: 9742 | W40: 1.42 | X40: 1.42 | Y40: 1.46 | Z40: 9886 | AA40: 0.4 | AB40: 79000
...

Sheet Balance Sheet
A1: Ticker | B1: FY | C1: Cash & Equivalents | D1: Cash, Cash Equiv. & Short Term Inv. | E1: Total Receivables | F1: Total Inventory | G1: Prepaid Expenses | H1: Other Current Assets | I1: Total Current Assets | J1: PP&E Gross | K1: Accumulated Depreciation, Total | L1: PP&E Net | M1: Goodwill | N1: Intangibles | O1: Long Term Investments | P1: Note Receivable - Long Term | Q1: Other Long Term Assets | R1: Total Assets | S1: Accounts Payable | T1: Accrued Expenses | U1: Current Port. of LT Debt/Capital Leases | V1: Notes Payable/Short Term Debt | W1: Other Current Liabilities | X1: Total Current Liabilities | Y1: Long Term Debt | Z1: Capital Lease Obligations | AA1: Total Long Term Debt | AB1: Deferred Income Tax | AC1: Other Liabilities, Total | AD1: Minority Interest | AE1: Total Liabilities | AF1: Common Stock | AG1: Additional Paid-In Capital | AH1: Retained Earnings (Accumulated Deficit) | AI1: Treasury Stock - Common | AJ1: Unrealized Gain (Loss) | AK1: Other Equity, Total | AL1: Total Equity | AM1: Total Liabilities & Shareholders' Equity | AN1: Total Common Shares Outstanding
A2: AMZN | B2: 46022 | C2: 86810 | D2: 123029 | E2: 60529 | F2: 38325 | G2: 6900 | H2: 300 | I2: 229083 | J2: 620152 | K2: -177073 | L2: 443079 | M2: 23273 | N2: 9197 | O2: 5000 | Q2: 108410 | R2: 818042 | S2: 121909 | T2: 70415 | U2: 4650 | V2: 455 | W2: 20576 | X2: 218005 | Y2: 65648 | Z2: 18542 | AA2: 84190 | AC2: 104782 | AE2: 406977 | AF2: 112 | AG2: 140024 | AH2: 250536 | AI2: -7837 | AJ2: 30170 | AK2: -1940 | AL2: 411065 | AM2: 818042 | AN2: 10731
A3: AMZN | B3: 45657 | C3: 78779 | D3: 101202 | E3: 48904 | F3: 34214 | G3: 6300 | H3: 247 | I3: 190867 | J3: 470196 | K3: -141390 | L3: 328806 | M3: 23074 | N3: 8602 | O3: 4600 | Q3: 68945 | R3: 624894 | S3: 94363 | T3: 60110 | U3: 6704 | V3: 151 | W3: 18103 | X3: 179431 | Y3: 52623 | Z3: 16327 | AA3: 68950 | AC3: 90543 | AE3: 338924 | AF3: 111 | AG3: 120864 | AH3: 172866 | AI3: -7837 | AK3: -34 | AL3: 285970 | AM3: 624894 | AN3: 10593
A4: AMZN | B4: 45291 | C4: 73387 | D4: 86780 | E4: 46356 | F4: 33318 | G4: 5400 | H4: 497 | I4: 172351 | J4: 396801 | K4: -120111 | L4: 276690 | M4: 22789 | N4: 7687 | O4: 5700 | Q4: 42637 | R4: 527854 | S4: 84981 | T4: 53765 | U4: 10797 | V4: 147 | W4: 15227 | X4: 164917 | Y4: 58314 | Z4: 16677 | AA4: 74991 | AC4: 86071 | AE4: 325979 | AF4: 109 | AG4: 99025 | AH4: 113618 | AI4: -7837 | AK4: -3040 | AL4: 201875 | AM4: 527854 | AN4: 10383
A5: AMZN | B5: 44926 | C5: 53888 | D5: 70026 | E5: 42002 | F5: 34405 | H5: 358 | I5: 146791 | J5: 349853 | K5: -97015 | L5: 252838 | M5: 20288 | N5: 6097 | O5: 5000 | Q5: 31661 | R5: 462675 | S5: 79600 | T5: 46904 | U5: 7662 | V5: 8000 | W5: 13227 | X5: 155393 | Y5: 67150 | Z5: 18086 | AA5: 85236 | AC5: 76003 | AE5: 316632 | AF5: 108 | AG5: 75066 | AH5: 83193 | AI5: -7837 | AK5: -4487 | AL5: 146043 | AM5: 462675 | AN5: 10242
A6: AMZN | B6: 44561 | C6: 36220 | D6: 96049 | E6: 32649 | F6: 32640 | H6: 242 | I6: 161580 | J6: 294882 | K6: -78519 | L6: 216363 | M6: 15371 | N6: 5107 | O6: 20300 | Q6: 1828 | R6: 420549 | S6: 78664 | T6: 40962 | U6: 9770 | V6: 1043 | W6: 11827 | X6: 142266 | Y6: 48744 | Z6: 21870 | AA6: 70614 | AB6: 494 | AC6: 68930 | AE6: 282304 | AF6: 5 | AG6: 55538 | AH6: 85915 | AI6: -1837 | AK6: -1376 | AL6: 138245 | AM6: 420549 | AN6: 10180
A7: AMZN | B7: 44196 | C7: 42122 | D7: 84396 | E7: 24309 | F7: 23795 | G7: 1 | H7: 232 | I7: 132733 | J7: 211101 | K7: -60434 | L7: 150667 | M7: 15017 | N7: 4981 | O7: 3200 | Q7: 14597 | R7: 321195 | S7: 72539 | T7: 31773 | U7: 11640 | V7: 725 | W7: 9708 | X7: 126385 | Y7: 31816 | Z7: 21460 | AA7: 53276 | AC7: 48130 | AE7: 227791 | AF7: 5 | AG7: 42865 | AH7: 52551 | AI7: -1837 | AK7: -180 | AL7: 93404 | AM7: 321195 | AN7: 10060
A8: AMZN | B8: 43830 | C8: 36092 | D8: 55021 | E8: 20540 | F8: 20497 | G8: 1 | H8: 275 | I8: 96334 | J8: 144821 | K8: -46975 | L8: 97846 | M8: 14754 | N8: 4049 | O8: 679 | Q8: 11586 | R8: 225248 | S8: 47183 | T8: 21248 | U8: 11191 | V8: 0 | W8: 8190 | X8: 87812 | Y8: 23414 | Z8: 17095 | AA8: 40509 | AC8: 34867 | AE8: 163188 | AF8: 5 | AG8: 33658 | AH8: 31220 | AI8: -1837 | AK8: -986 | AL8: 62060 | AM8: 225248 | AN8: 9960
A9: AMZN | B9: 43465 | C9: 31750 | D9: 41250 | E9: 16677 | F9: 17174 | I9: 75101 | J9: 95770 | K9: -33973 | L9: 61797 | M9: 14548 | N9: 4110 | O9: 518 | Q9: 6574 | R9: 162648 | S9: 38192 | T9: 14161 | U9: 9502 | V9: 0 | W9: 6536 | X9: 68391 | Y9: 23495 | Z9: 16292 | AA9: 39787 | AB9: 1490 | AC9: 9431 | AE9: 119099 | AF9: 5 | AG9: 26791 | AH9: 19625 | AI9: -1837 | AK9: -1035 | AL9: 43549 | AM9: 162648 | AN9: 9820
A10: AMZN | B10: 43100 | C10: 20522 | D10: 30986 | E10: 13164 | F10: 16047 | I10: 60197 | J10: 68573 | K10: -19707 | L10: 48866 | M10: 13350 | N10: 3371 | O10: 415 | Q10: 5111 | R10: 131310 | S10: 34616 | T10: 11949 | U10: 6221 | V10: 0 | W10: 5097 | X10: 57883 | Y10: 24743 | Z10: 13183 | AA10: 37926 | AB10: 990 | AC10: 6802 | AE10: 103601 | AF10: 5 | AG10: 21389 | AH10: 8636 | AI10: -1837 | AJ10: -16 | AK10: -468 | AL10: 27709 | AM10: 131310 | AN10: 9680
A11: AMZN | B11: 42735 | C11: 19334 | D11: 25981 | E11: 8339 | F11: 11461 | I11: 45781 | J11: 42441 | K11: -13327 | L11: 29114 | M11: 3784 | N11: 854 | O11: 242 | Q11: 3627 | R11: 83402 | S11: 25309 | T11: 8542 | U11: 5197 | V11: 0 | W11: 4768 | X11: 43816 | Y11: 7694 | Z11: 7519 | AA11: 15213 | AB11: 392 | AC11: 4696 | AE11: 64117 | AF11: 5 | AG11: 17186 | AH11: 4916 | AI11: -1837 | AJ11: 16 | AK11: -1001 | AL11: 19285 | AM11: 83402 | AN11: 9540
A12: AMZN | B12: 42369 | C12: 15890 | D12: 19808 | E12: 5654 | F12: 10243 | I12: 35705 | J12: 30053 | K12: -8215 | L12: 21838 | M12: 3759 | Q12: 3445 | R12: 64747 | S12: 20397 | T12: 7273 | U12: 3099 | V12: 0 | W12: 3118 | X12: 33887 | Y12: 8227 | Z12: 5900 | AA12: 14127 | AC12: 3349 | AE12: 51363 | AF12: 5 | AG12: 13394 | AH12: 2545 | AI12: -1837 | AK12: -723 | AL12: 13384 | AM12: 64747 | AN12: 9420
A13: AMZN | B13: 42004 | C13: 14557 | D13: 17416 | E13: 5612 | F13: 8299 | I13: 31327 | J13: 22730 | K13: -5763 | L13: 16967 | M13: 3319 | N13: 764 | O13: 209 | Q13: 1919 | R13: 54505 | S13: 16459 | T13: 6207 | U13: 3600 | V13: 0 | W13: 1823 | X13: 28089 | Y13: 8265 | Z13: 4224 | AA13: 12489 | AB13: 1021 | AC13: 2165 | AE13: 43764 | AF13: 5 | AG13: 11135 | AH13: 1949 | AI13: -1837 | AJ13: 1 | AK13: -512 | AL13: 10741 | AM13: 54505 | AN13: 9300
A14: AMZN | B14: 41639 | C14: 8658 | D14: 12447 | E14: 4767 | F14: 7411 | I14: 24625 | J14: 14809 | K14: -3860 | L14: 10949 | M14: 2655 | N14: 645 | O14: 127 | Q14: 1158 | R14: 40159 | S14: 15133 | T14: 4952 | U14: 1736 | V14: 0 | W14: 1159 | X14: 22980 | Y14: 3191 | Z14: 1990 | AA14: 5181 | AC14: 2252 | AE14: 30413 | AF14: 5 | AG14: 9573 | AH14: 2190 | AI14: -1837 | AJ14: 2 | AK14: -187 | AL14: 9746 | AM14: 40159 | AN14: 9180
A15: AMZN | B15: 41274 | C15: 8084 | D15: 11448 | E15: 3364 | F15: 6031 | H15: 453 | I15: 21296 | J15: 9582 | K15: -2522 | L15: 7060 | M15: 2552 | N15: 725 | O15: 140 | Q15: 782 | R15: 32555 | S15: 13318 | T15: 5129 | U15: 555 | V15: 0 | X15: 19002 | Y15: 3084 | Z15: 746 | AA15: 3830 | AC15: 1531 | AE15: 24363 | AF15: 5 | AG15: 8347 | AH15: 1916 | AI15: -1837 | AJ15: 11 | AK15: -250 | AL15: 8192 | AM15: 32555 | AN15: 9080
A16: AMZN | B16: 40908 | C16: 5269 | D16: 9576 | E16: 2571 | F16: 4992 | H16: 351 | I16: 17490 | J16: 5786 | K16: -1369 | L16: 4417 | M16: 1955 | N16: 647 | Q16: 769 | R16: 25278 | S16: 11145 | T16: 2765 | U16: 524 | V16: 0 | W16: 462 | X16: 14896 | Y16: 255 | Z16: 1160 | AA16: 1415 | AC16: 1210 | AE16: 17521 | AF16: 5 | AG16: 6990 | AH16: 1955 | AI16: -877 | AJ16: 10 | AK16: -326 | AL16: 7757 | AM16: 25278 | AN16: 9100
A17: AMZN | B17: 40543 | C17: 3777 | D17: 8762 | E17: 1587 | F17: 3202 | H17: 196 | I17: 13747 | J17: 3256 | K17: -842 | L17: 2414 | M17: 1349 | N17: 563 | Q17: 724 | R17: 18797 | S17: 8051 | T17: 1860 | U17: 0 | V17: 0 | W17: 461 | X17: 10372 | Y17: 184 | Z17: 457 | AA17: 641 | AC17: 920 | AE17: 11933 | AF17: 5 | AG17: 6325 | AH17: 1324 | AI17: -600 | AK17: -190 | AL17: 6864 | AM17: 18797 | AN17: 9020
A18: AMZN | B18: 40178 | C18: 3444 | D18: 6366 | E18: 988 | F18: 2171 | H18: 272 | I18: 9797 | J18: 1915 | K18: -625 | L18: 1290 | M18: 1234 | N18: 567 | Q18: 925 | R18: 13813 | S18: 5605 | T18: 1248 | U18: 0 | V18: 0 | W18: 511 | X18: 7364 | Y18: 109 | Z18: 143 | AA18: 252 | AC18: 940 | AE18: 8556 | AF18: 5 | AG18: 5736 | AH18: 172 | AI18: -600 | AK18: -56 | AL18: 5257 | AM18: 13813 | AN18: 8880
A19: AMZN | B19: 39813 | C19: 2769 | D19: 3727 | E19: 827 | F19: 1399 | H19: 204 | I19: 6157 | J19: 1409 | K19: -555 | L19: 854 | M19: 438 | N19: 160 | Q19: 705 | R19: 8314 | S19: 3594 | T19: 902 | U19: 59 | V19: 0 | W19: 191 | X19: 4746 | Y19: 409 | AA19: 409 | AC19: 487 | AE19: 5642 | AF19: 4 | AG19: 4121 | AH19: -730 | AI19: -600 | AK19: -123 | AL19: 2672 | AM19: 8314 | AN19: 8560
A20: AMZN | B20: 39447 | C20: 2539 | D20: 3112 | E20: 682 | F20: 1200 | G20: 23 | H20: 147 | I20: 5164 | J20: 1023 | K20: -480 | L20: 543 | M20: 222 | Q20: 556 | R20: 6485 | S20: 2795 | T20: 919 | U20: 0 | V20: 0 | X20: 3714 | Y20: 1282 | AA20: 1282 | AC20: 292 | AE20: 5288 | AF20: 4 | AG20: 3063 | AH20: -1375 | AI20: -500 | AK20: 5 | AL20: 1197 | AM20: 6485 | AN20: 8320
A21: AMZN | B21: 39082 | C21: 1022 | D21: 2019 | E21: 382 | F21: 877 | G21: 17 | H21: 78 | I21: 3373 | J21: 824 | K21: -367 | L21: 457 | M21: 195 | Q21: 338 | R21: 4363 | S21: 1816 | T21: 716 | U21: 0 | V21: 0 | X21: 2532 | Y21: 1247 | AA21: 1247 | AC21: 153 | AE21: 3932 | AF21: 4 | AG21: 2517 | AH21: -1837 | AI21: -252 | AK21: -1 | AL21: 431 | AM21: 4363 | AN21: 8280
A22: MSFT | B22: 46022 | C22: 30242 | D22: 94565 | E22: 78105 | F22: 938 | H22: 17523 | I22: 191131 | J22: 323442 | K22: -93653 | L22: 229789 | M22: 119509 | N22: 22604 | O22: 15405 | P22: 5200 | Q22: 35365 | R22: 619003 | S22: 27724 | T22: 19133 | U22: 6171 | V22: 0 | W22: 88190 | X22: 141218 | Y22: 40152 | Z22: 43000 | AA22: 83152 | AB22: 2835 | AC22: 48319 | AE22: 275524 | AF22: 46462.5 | AG22: 62632.5 | AH22: 237731 | AJ22: -1051 | AK22: -2296 | AL22: 343479 | AM22: 619003 | AN22: 7434
A23: MSFT | B23: 45657 | C23: 18315 | D23: 75543 | E23: 67424 | F23: 1246 | H23: 15521 | I23: 159734 | J23: 230973 | K23: -76421 | L23: 154552 | M23: 119220 | N23: 27597 | O23: 14600 | P23: 4900 | Q23: 31560 | R23: 512163 | S23: 21996 | T23: 16144 | U23: 4598 | V23: 6693 | W23: 75855 | X23: 125286 | Y23: 42688 | Z23: 24796 | AA23: 67484 | AB23: 2618 | AC23: 48298 | AE23: 243686 | AF23: 46462.5 | AG23: 54460.5 | AH23: 173144 | AJ23: -2625 | AK23: -2965 | AL23: 268477 | AM23: 512163 | AN23: 7434
A24: MSFT | B24: 45291 | C24: 34704 | D24: 111262 | E24: 48688 | F24: 2500 | H24: 21807 | I24: 184257 | J24: 178238 | K24: -68251 | L24: 109987 | M24: 67886 | N24: 9366 | O24: 9879 | P24: 4500 | Q24: 26101 | R24: 411976 | S24: 18095 | T24: 13418 | U24: 6444 | V24: 0 | W24: 66192 | X24: 104149 | Y24: 41990 | Z24: 15870 | AA24: 57860 | AB24: 433 | AC24: 43311 | AE24: 205753 | AF24: 46450 | AG24: 47268 | AH24: 118848 | AJ24: -3582 | AK24: -2761 | AL24: 206223 | AM24: 411976 | AN24: 7432
A25: MSFT | B25: 44926 | C25: 13931 | D25: 104757 | E25: 44261 | F25: 3742 | H25: 16924 | I25: 169684 | J25: 147206 | K25: -59660 | L25: 87546 | M25: 67524 | N25: 11298 | O25: 6891 | P25: 3800 | Q25: 18097 | R25: 364840 | S25: 19000 | T25: 12889 | U25: 3809 | V25: 0 | W25: 59384 | X25: 95082 | Y25: 47032 | Z25: 13842 | AA25: 60874 | AB25: 230 | AC25: 42112 | AE25: 198298 | AF25: 46650 | AG25: 40289 | AH25: 84281 | AJ25: -2138 | AK25: -2540 | AL25: 166542 | AM25: 364840 | AN25: 7464
A26: MSFT | B26: 44561 | C26: 14224 | D26: 130334 | E26: 38043 | F26: 2636 | H26: 13393 | I26: 184406 | J26: 122154 | K26: -51351 | L26: 70803 | M26: 49711 | N26: 7800 | O26: 5984 | P26: 3400 | Q26: 11675 | R26: 333779 | S26: 15163 | T26: 12019 | U26: 8863 | V26: 0 | W26: 52612 | X26: 88657 | Y26: 50074 | Z26: 11750 | AA26: 61824 | AB26: 198 | AC26: 41112 | AE26: 191791 | AF26: 46993.8 | AG26: 36117.25 | AH26: 57055 | AJ26: 3222 | AK26: -1400 | AL26: 141988 | AM26: 333779 | AN26: 7519
A27: MSFT | B27: 44196 | C27: 13576 | D27: 136527 | E27: 32011 | F27: 1895 | H27: 11482 | I27: 181915 | J27: 96101 | K27: -43197 | L27: 52904 | M27: 43351 | N27: 7038 | O27: 2965 | P27: 2700 | Q27: 10438 | R27: 301311 | S27: 12530 | T27: 9490 | U27: 4289 | V27: 0 | W27: 46001 | X27: 72310 | Y27: 59578 | Z27: 8956 | AA27: 68534 | AB27: 204 | AC27: 41959 | AE27: 183007 | AF27: 47318.8 | AG27: 33233.25 | AH27: 34566 | AJ27: 5478 | AK27: -2292 | AL27: 118304 | AM27: 301311 | AN27: 7571
A28: MSFT | B28: 43830 | C28: 11356 | D28: 133819 | E28: 29524 | F28: 2063 | H28: 10146 | I28: 175552 | J28: 79186 | K28: -35330 | L28: 43856 | M28: 42026 | N28: 7750 | O28: 2649 | P28: 2200 | Q28: 12523 | R28: 286556 | S28: 9382 | T28: 8345 | U28: 5833 | V28: 0 | W28: 45860 | X28: 69420 | Y28: 66662 | Z28: 6257 | AA28: 72919 | AB28: 233 | AC28: 41654 | AE28: 184226 | AF28: 49679.5 | AG28: 28840.5 | AH28: 24150 | AJ28: 1488 | AK28: -1828 | AL28: 102330 | AM28: 286556 | AN28: 7643
A29: MSFT | B29: 43465 | C29: 11946 | D29: 133650 | E29: 26481 | F29: 2662 | H29: 6869 | I29: 169662 | J29: 65369 | K29: -29223 | L29: 36146 | M29: 35683 | N29: 8053 | O29: 1862 | P29: 1800 | Q29: 5642 | R29: 258848 | S29: 8617 | T29: 7502 | U29: 4174 | V29: 0 | W29: 38195 | X29: 58488 | Y29: 72242 | Z29: 4125 | AA29: 76367 | AB29: 541 | AC29: 40734 | AE29: 176130 | AF29: 47981.2 | AG29: 23241.75 | AH29: 13682 | AJ29: -892 | AK29: -1295 | AL29: 82718 | AM29: 258848 | AN29: 7677
A30: MSFT | B30: 43100 | C30: 7663 | D30: 132881 | E30: 22431 | F30: 2181 | H30: 5203 | I30: 162696 | J30: 54468 | K30: -24179 | L30: 30289 | M30: 35122 | N30: 10106 | O30: 5956 | Q30: 6143 | R30: 250312 | S30: 7390 | T30: 5819 | U30: 1162 | V30: 9072 | W30: 32302 | X30: 55745 | Y30: 76073 | Z30: 2425 | AA30: 78498 | AB30: 5734 | AC30: 22624 | AE30: 162601 | AF30: 48175 | AG30: 21140 | AH30: 17769 | AJ30: 1825 | AK30: -1198 | AL30: 87711 | AM30: 250312 | AN30: 7708
A31: MSFT | B31: 42735 | C31: 6510 | D31: 113167 | E31: 18277 | F31: 2251 | H31: 5965 | I31: 139660 | J31: 38156 | K31: -19800 | L31: 18356 | M31: 17872 | N31: 3733 | O31: 10413 | Q31: 3434 | R31: 193468 | S31: 6898 | T31: 5264 | U31: 25 | V31: 12904 | W31: 34266 | X31: 59357 | Y31: 40557 | Z31: 761 | AA31: 41318 | AB31: 1476 | AC31: 19320 | AE31: 121471 | AF31: 48800 | AG31: 19378 | AH31: 2282 | AJ31: 2941 | AK31: -1404 | AL31: 71997 | AM31: 193468 | AN31: 7808
A32: MSFT | B32: 42369 | C32: 5595 | D32: 96282 | E32: 17908 | F32: 2902 | H32: 5705 | I32: 122797 | J32: 32337 | K32: -17606 | L32: 14731 | M32: 16939 | N32: 4835 | O32: 12028 | Q32: 3142 | R32: 174472 | S32: 6591 | T32: 5096 | U32: 2499 | V32: 4985 | W32: 30476 | X32: 49647 | Y32: 27808 | AA32: 27808 | AB32: 1295 | AC32: 15639 | AE32: 94389 | AF32: 50168.8 | AG32: 18296.25 | AH32: 9096 | AJ32: 3169 | AK32: -647 | AL32: 80083 | AM32: 174472 | AN32: 8027
A33: MSFT | B33: 42004 | C33: 8669 | D33: 85465 | E33: 19544 | F33: 2660 | H33: 6577 | I33: 114246 | J33: 27804 | K33: -14793 | L33: 13011 | M33: 20127 | N33: 6981 | O33: 14590 | Q33: 3429 | R33: 172384 | S33: 7432 | T33: 4797 | U33: 0 | V33: 2000 | W33: 31396 | X33: 45625 | Y33: 20645 | AA33: 20645 | AB33: 2728 | AC33: 13602 | AE33: 82600 | AF33: 51493.8 | AG33: 16872.25 | AH33: 17710 | AJ33: 3531 | AK33: 177 | AL33: 89784 | AM33: 172384 | AN33: 8239
A34: MSFT | B34: 41639 | C34: 3804 | D34: 76775 | E34: 17486 | F34: 1938 | H34: 5267 | I34: 101466 | J34: 22504 | K34: -12513 | L34: 9991 | M34: 14655 | N34: 3083 | O34: 10844 | Q34: 2392 | R34: 142431 | S34: 4828 | T34: 4117 | U34: 2999 | V34: 0 | W34: 25473 | X34: 37417 | Y34: 12601 | AA34: 12601 | AB34: 1709 | AC34: 11760 | AE34: 63487 | AF34: 52050 | AG34: 15256 | AH34: 9895 | AJ34: 1794 | AK34: -51 | AL34: 78944 | AM34: 142431 | AN34: 8328
A35: MSFT | B35: 41274 | C35: 6938 | D35: 63040 | E35: 15780 | F35: 1137 | H35: 5127 | I35: 85084 | J35: 19231 | K35: -10962 | L35: 8269 | M35: 13452 | N35: 3170 | O35: 9776 | Q35: 1520 | R35: 121271 | S35: 4175 | T35: 3875 | U35: 1231 | V35: 0 | W35: 23407 | X35: 32688 | Y35: 10713 | AA35: 10713 | AB35: 1893 | AC35: 9614 | AE35: 54908 | AF35: 65797 | AH35: -856 | AJ35: 1431 | AK35: -9 | AL35: 66363 | AM35: 121271 | AN35: 8381
A36: MSFT | B36: 40908 | C36: 9610 | D36: 52772 | E36: 14987 | F36: 1372 | H36: 5787 | I36: 74918 | J36: 17991 | K36: -9829 | L36: 8162 | M36: 12581 | N36: 744 | O36: 10865 | Q36: 1434 | R36: 108704 | S36: 4197 | T36: 3575 | U36: 0 | V36: 0 | W36: 21002 | X36: 28774 | Y36: 11921 | AA36: 11921 | AB36: 1456 | AC36: 9470 | AE36: 51621 | AF36: 63415 | AH36: -8195 | AJ36: 1821 | AK36: 42 | AL36: 57083 | AM36: 108704 | AN36: 8376
A37: MSFT | B37: 40543 | C37: 5505 | D37: 36788 | E37: 13014 | F37: 740 | H37: 5134 | I37: 55676 | J37: 16259 | K37: -8629 | L37: 7630 | M37: 12394 | N37: 1158 | O37: 7754 | Q37: 1501 | R37: 86113 | S37: 4025 | T37: 3283 | U37: 0 | V37: 1000 | W37: 17839 | X37: 26147 | Y37: 4939 | AA37: 4939 | AB37: 229 | AC37: 8623 | AE37: 39938 | AF37: 62856 | AH37: -17736 | AJ37: 767 | AK37: 288 | AL37: 46175 | AM37: 86113 | AN37: 8668
A38: MSFT | B38: 40178 | C38: 6076 | D38: 31447 | E38: 11192 | F38: 717 | H38: 5924 | I38: 49280 | J38: 15082 | K38: -7547 | L38: 7535 | M38: 12503 | N38: 1759 | O38: 4933 | Q38: 1878 | R38: 77888 | S38: 3324 | T38: 3156 | U38: 0 | V38: 2000 | W38: 18554 | X38: 27034 | Y38: 3746 | AA38: 3746 | AB38: 0 | AC38: 7550 | AE38: 38330 | AF38: 62382 | AH38: -23793 | AJ38: 502 | AK38: 467 | AL38: 39558 | AM38: 77888 | AN38: 8908
A39: MSFT | B39: 39813 | C39: 10339 | D39: 23662 | E39: 13589 | F39: 985 | H39: 5006 | I39: 43242 | J39: 12544 | K39: -6302 | L39: 6242 | M39: 12108 | N39: 1973 | O39: 6588 | Q39: 2640 | R39: 72793 | S39: 4034 | T39: 2934 | U39: 0 | V39: 0 | W39: 22918 | X39: 29886 | Y39: 0 | AA39: 0 | AC39: 6621 | AE39: 36507 | AF39: 62849 | AH39: -27703 | AK39: 1140 | AL39: 36286 | AM39: 72793 | AN39: 9151
A40: MSFT | B40: 39447 | C40: 6111 | D40: 23411 | E40: 11338 | F40: 1127 | H40: 4292 | I40: 40168 | J40: 9366 | K40: -5016 | L40: 4350 | M40: 4760 | N40: 878 | O40: 10117 | Q40: 2898 | R40: 63171 | S40: 3247 | T40: 2325 | U40: 0 | V40: 0 | W40: 18182 | X40: 23754 | AA40: 0 | AC40: 8320 | AE40: 32074 | AF40: 60557 | AH40: -31114 | AK40: 1654 | AL40: 31097 | AM40: 63171 | AN40: 9380
...

Sheet Cash Flow
A1: Ticker | B1: FY | C1: Net Income | D1: Changes in Working Capital | E1: Cash from Operating Activities | F1: Capital Expenditures | G1: Sale of Fixed Assets | H1: Acquisition of Business | I1: Sale/Maturity of Investment | J1: Other Investing Cash Flow Items, Total | K1: Cash from Investing Activities | L1: Short Term Debt | M1: Issuance (Retirement) of Debt | N1: Issuance (Retirement) of Stock | O1: Total Cash Dividends Paid | P1: Cash from Financing Activities | Q1: Foreign Exchange Effects | R1: Net Change in Cash | S1: Net Cash - Beginning Balance | T1: Net Cash - Ending Balance
A2: AMZN | B2: 46022 | C2: 77670 | D2: -19969 | E2: 139514 | F2: -131819 | G2: 3499 | H2: -3841 | I2: 44386 | J2: -10726 | K2: -142545 | L2: 894 | M2: 9661 | P2: 9661 | Q2: 1164 | R2: 7794 | S2: 82312 | T2: 90106
A3: AMZN | B3: 45657 | C3: 59248 | D3: -15541 | E3: 115877 | F3: -82999 | G3: 5341 | H3: -7082 | I3: 16403 | J3: -11343 | K3: -94342 | L3: 82 | M3: -11812 | N3: 0 | P3: -11812 | Q3: -1301 | R3: 8422 | S3: 73890 | T3: 82312
A4: AMZN | B4: 45291 | C4: 30425 | D4: -11541 | E4: 84946 | F4: -52729 | G4: 4596 | H4: -5839 | I4: 5627 | J4: 2896 | K4: -49833 | L4: -7548 | M4: -15879 | N4: 0 | P4: -15879 | Q4: 403 | R4: 19637 | S4: 54253 | T4: 73890
A5: AMZN | B5: 44926 | C5: -2722 | D5: -20886 | E5: 46752 | F5: -63645 | G5: 5324 | H5: -8316 | I5: 31601 | J5: 26044 | K5: -37601 | L5: 3999 | M5: 15718 | N5: -6000 | P5: 9718 | Q5: -1093 | R5: 17776 | S5: 36477 | T5: 54253
A6: AMZN | B6: 44561 | C6: 33364 | D6: -19611 | E6: 46327 | F6: -61053 | G6: 5657 | H6: -1985 | I6: 59384 | J6: 2899 | K6: -58154 | L6: 203 | M6: 6291 | P6: 6291 | Q6: -364 | R6: -5900 | S6: 42377 | T6: 36477
A7: AMZN | B7: 44196 | C7: 21331 | D7: 13481 | E7: 66064 | F7: -40140 | G7: 5096 | H7: -2325 | I7: 50237 | J7: -19471 | K7: -59611 | L7: 619 | M7: -1104 | P7: -1104 | Q7: 618 | R7: 5967 | S7: 36410 | T7: 42377
A8: AMZN | B8: 43830 | C8: 11588 | D8: -2438 | E8: 38514 | F8: -16861 | G8: 4172 | H8: -2461 | I8: 22681 | J8: -7420 | K8: -24281 | M8: -10066 | P8: -10066 | Q8: 70 | R8: 4237 | S8: 32173 | T8: 36410
A9: AMZN | B9: 43465 | C9: 10073 | D9: -1043 | E9: 30723 | F9: -13427 | G9: 2104 | H9: -2186 | I9: 8240 | J9: 1058 | K9: -12369 | M9: -7686 | P9: -7686 | Q9: -351 | R9: 10317 | S9: 21856 | T9: 32173
A10: AMZN | B10: 43100 | C10: 3033 | D10: -242 | E10: 18365 | F10: -11955 | G10: 1897 | H10: -13972 | I10: 9677 | J10: -15129 | K10: -27084 | M10: 9928 | P10: 9928 | Q10: 713 | R10: 1922 | S10: 19934 | T10: 21856
A11: AMZN | B11: 42735 | C11: 2371 | D11: 3847 | E11: 17203 | F11: -7804 | G11: 1067 | H11: -116 | I11: 4577 | J11: -1712 | K11: -9516 | M11: -3716 | P11: -3716 | Q11: -212 | R11: 3759 | S11: 16175 | T11: 19934
A12: AMZN | B12: 42369 | C12: 596 | D12: 2557 | E12: 11920 | F12: -4589 | H12: -795 | I12: 3025 | J12: -1861 | K12: -6450 | M12: -3882 | P12: -3763 | Q12: -374 | R12: 1333 | S12: 14557 | T12: 15890
A13: AMZN | B13: 42004 | C13: -241 | D13: 974 | E13: 6842 | F13: -4893 | H13: -979 | I13: 3349 | J13: -172 | K13: -5065 | M13: 4426 | N13: 0 | P13: 4432 | Q13: -310 | R13: 5899 | S13: 8658 | T13: 14557
A14: AMZN | B14: 41639 | C14: 274 | D14: 767 | E14: 5475 | F14: -3444 | H14: -312 | I14: 2306 | J14: -832 | K14: -4276 | M14: -617 | N14: 0 | P14: -539 | Q14: -86 | R14: 574 | S14: 8084 | T14: 8658
A15: AMZN | B15: 41274 | C15: -39 | D15: 1523 | E15: 4180 | F15: -3785 | H15: -745 | I15: 4237 | J15: 190 | K15: -3595 | M15: 2790 | N15: -960 | P15: 2259 | Q15: -29 | R15: 2815 | S15: 5269 | T15: 8084
A16: AMZN | B16: 40908 | C16: 631 | D16: 1464 | E16: 3903 | F16: -1811 | H16: -705 | I16: 6843 | J16: -119 | K16: -1930 | M16: -267 | N16: -277 | P16: -482 | Q16: 1 | R16: 1492 | S16: 3777 | T16: 5269
A17: AMZN | B17: 40543 | C17: 1152 | D17: 1581 | E17: 3495 | F17: -979 | H17: -352 | I17: 4250 | J17: -2381 | K17: -3360 | M17: -78 | N17: 0 | P17: 181 | Q17: 17 | R17: 333 | S17: 3444 | T17: 3777
A18: AMZN | B18: 40178 | C18: 902 | D18: 1612 | E18: 3293 | F18: -373 | H18: -40 | I18: 1966 | J18: -1964 | K18: -2337 | M18: -385 | N18: 0 | P18: -280 | Q18: -1 | R18: 675 | S18: 2769 | T18: 3444
A19: AMZN | B19: 39813 | C19: 645 | D19: 714 | E19: 1697 | F19: -333 | H19: -494 | I19: 1305 | J19: -866 | K19: -1199 | M19: -268 | N19: -89 | P19: -198 | Q19: -70 | R19: 230 | S19: 2539 | T19: 2769
A20: AMZN | B20: 39447 | C20: 476 | D20: 832 | E20: 1405 | F20: -224 | H20: -75 | I20: 1271 | J20: 266 | K20: 42 | M20: -50 | N20: -157 | P20: 50 | Q20: 20 | R20: 1517 | S20: 1022 | T20: 2539
A21: AMZN | B21: 39082 | C21: 190 | D21: 284 | E21: 702 | F21: -216 | H21: -32 | I21: 1845 | J21: -117 | K21: -333 | M21: -285 | N21: -217 | P21: -400 | Q21: 40 | R21: 9 | S21: 1013 | T21: 1022
A22: MSFT | B22: 46022 | C22: 101832 | D22: -5350 | E22: 136162 | F22: -64551 | H22: -5978 | I22: 25388 | J22: -8048 | K22: -72599 | L22: -5746 | M22: -8962 | N22: -16364 | O22: -24082 | P22: -51699 | Q22: 63 | R22: 11927 | S22: 18315 | T22: 30242
A23: MSFT | B23: 45657 | C23: 88136 | D23: 1824 | E23: 118548 | F23: -44477 | H23: -69132 | I23: 35669 | J23: -52493 | K23: -96970 | L23: 5250 | M23: 575 | N23: -15252 | O23: -21771 | P23: -37757 | Q23: -210 | R23: -16389 | S23: 34704 | T23: 18315
A24: MSFT | B24: 45291 | C24: 72361 | D24: -2388 | E24: 87582 | F24: -28107 | H24: -1670 | I24: 47864 | J24: 5427 | K24: -22680 | M24: -2750 | N24: -20379 | O24: -19800 | P24: -43935 | Q24: -194 | R24: 20773 | S24: 13931 | T24: 34704
A25: MSFT | B25: 44926 | C25: 72738 | D25: 446 | E25: 89035 | F25: -23886 | H25: -22038 | I25: 44894 | J25: -6425 | K25: -30311 | M25: -9023 | N25: -30855 | O25: -18135 | P25: -58876 | Q25: -141 | R25: -293 | S25: 14224 | T25: 13931
A26: MSFT | B26: 44561 | C26: 61271 | D26: -936 | E26: 76740 | F26: -20622 | H26: -8909 | I26: 65800 | J26: -6955 | K26: -27577 | M26: -3750 | N26: -25692 | O26: -16521 | P26: -48486 | Q26: -29 | R26: 648 | S26: 13576 | T26: 14224
A27: MSFT | B27: 44196 | C27: 44281 | D27: -1483 | E27: 60675 | F27: -15441 | H27: -2521 | I27: 84170 | J27: 3218 | K27: -12223 | L27: 0 | M27: -5518 | N27: -21625 | O27: -15137 | P27: -46031 | Q27: -201 | R27: 2220 | S27: 11356 | T27: 13576
A28: MSFT | B28: 43830 | C28: 39240 | D28: 3866 | E28: 52185 | F28: -13925 | H28: -2388 | I28: 58237 | J28: -1848 | K28: -15773 | L28: 0 | M28: -4000 | N28: -18401 | O28: -13811 | P28: -36887 | Q28: -115 | R28: -590 | S28: 11946 | T28: 11356
A29: MSFT | B29: 43465 | C29: 16571 | D29: 20467 | E29: 43884 | F29: -11632 | H29: -888 | I29: 143937 | J29: 5571 | K29: -6061 | L29: -7324 | M29: -10201 | N29: -9719 | O29: -12699 | P29: -33590 | Q29: 50 | R29: 4283 | S29: 7663 | T29: 11946
A30: MSFT | B30: 43100 | C30: 21204 | D30: 1652 | E30: 39507 | F30: -8129 | H30: -25944 | I30: 164394 | J30: -38652 | K30: -46781 | L30: -4963 | M30: 31459 | N30: -11016 | O30: -11845 | P30: 8408 | Q30: 19 | R30: 1153 | S30: 6510 | T30: 7663
A31: MSFT | B31: 42735 | C31: 16798 | D31: -2076 | E31: 33325 | F31: -8343 | H31: -1393 | I31: 115341 | J31: -15607 | K31: -23950 | L31: 7195 | M31: 18283 | N31: -15301 | O31: -11006 | P31: -8393 | Q31: -67 | R31: 915 | S31: 5595 | T31: 6510
A32: MSFT | B32: 42369 | C32: 12193 | D32: 1513 | E32: 29080 | F32: -5944 | H32: -3723 | I32: 85861 | J32: -17057 | K32: -23001 | L32: 4481 | M32: 13661 | N32: -13809 | O32: -9882 | P32: -9080 | Q32: -73 | R32: -3074 | S32: 8669 | T32: 5595
A33: MSFT | B33: 42004 | C33: 22074 | D33: 624 | E33: 32231 | F33: -5485 | H33: -5937 | I33: 65366 | J33: -13348 | K33: -18833 | L33: 500 | M33: 6962 | N33: -6709 | O33: -8879 | P33: -8394 | Q33: -139 | R33: 4865 | S33: 3804 | T33: 8669
A34: MSFT | B34: 41639 | C34: 21863 | D34: -1375 | E34: 28833 | F34: -4257 | H34: -1584 | I34: 57594 | J34: -19554 | K34: -23811 | L34: 0 | M34: 3537 | N34: -4429 | O34: -7455 | P34: -8148 | Q34: -8 | R34: -3134 | S34: 6938 | T34: 3804
A35: MSFT | B35: 41274 | C35: 16978 | D35: -174 | E35: 31626 | F35: -2305 | H35: -10112 | I35: 45275 | J35: -22481 | K35: -24786 | L35: 0 | M35: 0 | N35: -3116 | O35: -6385 | P35: -9408 | Q35: -104 | R35: -2672 | S35: 9610 | T35: 6938
A36: MSFT | B36: 40908 | C36: 23150 | D36: -3003 | E36: 26994 | F36: -2355 | H36: -71 | I36: 22777 | J36: -12261 | K36: -14616 | L36: -186 | M36: 5960 | N36: -9133 | O36: -5180 | P36: -8376 | Q36: 103 | R36: 4105 | S36: 5505 | T36: 9610
A37: MSFT | B37: 40543 | C37: 18760 | D37: 661 | E37: 24073 | F37: -1977 | H37: -245 | I37: 22578 | J37: -9337 | K37: -11314 | L37: -991 | M37: 190 | N37: -8958 | O37: -4578 | P37: -13291 | Q37: -39 | R37: -571 | S37: 6076 | T37: 5505
A38: MSFT | B38: 40178 | C38: 14569 | D38: -178 | E38: 19037 | F38: -3119 | H38: -868 | I38: 25997 | J38: -12651 | K38: -15770 | L38: 1178 | M38: 5746 | N38: -8774 | O38: -4468 | P38: -7463 | Q38: -67 | R38: -4263 | S38: 10339 | T38: 6076
A39: MSFT | B39: 39813 | C39: 17681 | D39: -2435 | E39: 21612 | F39: -3182 | H39: -8053 | I39: 27729 | J39: -1405 | K39: -4587 | L39: 0 | M39: 0 | N39: -9039 | O39: -4015 | P39: -12934 | Q39: 137 | R39: 4228 | S39: 6111 | T39: 10339
A40: MSFT | B40: 39447 | C40: 14065 | D40: -961 | E40: 17796 | F40: -2264 | H40: -1150 | I40: 46187 | J40: 8353 | K40: 6089 | N40: -20793 | O40: -3805 | P40: -24544 | Q40: 56 | R40: -603 | S40: 6714 | T40: 6111
...

Sheet Ratios
A1: Ticker | B1: FY | C1: Revenue | D1: Gross profit | E1: EBITDA | F1: EBIT | G1: Pretax Income | H1: Net Income | I1: Cash + Investments | J1: Current Assets | K1: Total Assets | L1: Current Liabilities | M1: Equity | N1: Interest Expense | O1: Operating Leases | P1: Finance Leases | Q1: Total Debt | R1: Adjusted Total Debt | S1: D&A | T1: CAPEX | U1: Revenue Growth | V1: Gross Margin | W1: EBITDA Margin | X1: Operating Margin | Y1: Pretax Margin | Z1: Effective Tax Rate | AA1: Net Profit Margin | AB1: ROE | AC1: ROIC | AD1: ROA | AE1: Quick Ratio | AF1: Current Ratio | AG1: Net Debt | AH1: Debt / Equity | AI1: Debt / Capital | AJ1: Debt / Assets | AK1: Interest Coverage | AL1: Financial Leverage | AM1: CapEx / Revenue | AN1: PPE / Assets | AO1: Op Cash / Revenue | AP1: FCF Margin | AQ1: Book Value Per Share
A2: AMZN | B2: 46022 | C2: ='Income Statement'!C2 -> 716924 | D2: ='Income Statement'!E2 -> 360510 | E2: =F2+S2 -> 145731 | F2: ='Income Statement'!L2 -> 79975 | G2: ='Income Statement'!P2 -> 97311 | H2: ='Income Statement'!R2 -> 77670 | I2: ='Balance Sheet'!D2 -> 123029 | J2: ='Balance Sheet'!I2 -> 229083 | K2: ='Balance Sheet'!R2 -> 818042 | L2: ='Balance Sheet'!X2 -> 218005 | M2: ='Balance Sheet'!AL2 -> 411065 | N2: 2274 | O2: 89252 | P2: 12286 | Q2: 68851 | R2: =SUM(O2:Q2) -> 170389 | S2: 65756 | T2: =-'Cash Flow'!F2 -> 131819 | U2: =(C2-C3)/C3 -> 0.12377755 | V2: =D2/C2 -> 0.50285665 | W2: =E2/C2 -> 0.20327259 | X2: =F2/C2 -> 0.11155297 | Y2: =G2/C2 -> 0.13573405 | Z2: =(G2-H2)/G2 -> 0.20183741 | AA2: =H2/C2 -> 0.10833784 | AB2: =H2/M2 -> 0.18894822 | AC2: =(F2*(1-Z2))/(Q2-I2+M2) -> 0.17886069 | AD2: =H2/K2 -> 0.094946225 | AE2: =(I2+'Balance Sheet'!E2)/L2 -> 0.84198986 | AF2: =J2/L2 -> 1.0508153 | AG2: =Q2-I2 -> -54178 | AH2: =Q2/M2 -> 0.16749419 | AI2: =Q2/SUM(Q2,M2) -> 0.14346469 | AJ2: =Q2/K2 -> 0.084165605 | AK2: =F2/N2 -> 35.169305 | AL2: =K2/M2 -> 1.9900551 | AM2: =T2/C2 -> 0.18386747 | AN2: ='Balance Sheet'!J2/Ratios!K2 -> 0.75809311 | AO2: ='Cash Flow'!E2/C2 -> 0.19460082 | AP2: =('Cash Flow'!E2 +'Cash Flow'!F2)/Ratios!C2 -> 0.010733355 | AQ2: 38.31
A3: AMZN | B3: 45657 | C3: ='Income Statement'!C3 -> 637959 | D3: ='Income Statement'!E3 -> 311671 | E3: =F3+S3 -> 121388 | F3: ='Income Statement'!L3 -> 68593 | G3: ='Income Statement'!P3 -> 68614 | H3: ='Income Statement'!R3 -> 59248 | I3: ='Balance Sheet'!D3 -> 101202 | J3: ='Balance Sheet'!I3 -> 190867 | K3: ='Balance Sheet'!R3 -> 624894 | L3: ='Balance Sheet'!X3 -> 179431 | M3: ='Balance Sheet'!AL3 -> 285970 | N3: 2406 | O3: 79596 | P3: 10602 | Q3: 57791 | R3: =SUM(O3:Q3) -> 147989 | S3: 52795 | T3: =-'Cash Flow'!F3 -> 82999 | U3: =(C3-C4)/C4 -> 0.10990892 | V3: =D3/C3 -> 0.48854393 | W3: =E3/C3 -> 0.19027555 | X3: =F3/C3 -> 0.10751945 | Y3: =G3/C3 -> 0.10755237 | Z3: =(G3-H3)/G3 -> 0.13650275 | AA3: =H3/C3 -> 0.092871172 | AB3: =H3/M3 -> 0.20718257 | AC3: =(F3*(1-Z3))/(Q3-I3+M3) -> 0.24418746 | AD3: =H3/K3 -> 0.09481288 | AE3: =(I3+'Balance Sheet'!E3)/L3 -> 0.8365667 | AF3: =J3/L3 -> 1.0637348 | AG3: =Q3-I3 -> -43411 | AH3: =Q3/M3 -> 0.20208763 | AI3: =Q3/SUM(Q3,M3) -> 0.16811389 | AJ3: =Q3/K3 -> 0.092481285 | AK3: =F3/N3 -> 28.509144 | AL3: =K3/M3 -> 2.1851733 | AM3: =T3/C3 -> 0.13010084 | AN3: ='Balance Sheet'!J3/Ratios!K3 -> 0.75244121 | AO3: ='Cash Flow'!E3/C3 -> 0.18163706 | AP3: =('Cash Flow'!E3+'Cash Flow'!F3)/Ratios!C3 -> 0.051536227 | AQ3: 27
A4: AMZN | B4: 45291 | C4: ='Income Statement'!C4 -> 574785 | D4: ='Income Statement'!E4 -> 270046 | E4: =F4+S4 -> 85515 | F4: ='Income Statement'!L4 -> 36852 | G4: ='Income Statement'!P4 -> 37557 | H4: ='Income Statement'!R4 -> 30425 | I4: ='Balance Sheet'!D4 -> 86780 | J4: ='Balance Sheet'!I4 -> 172351 | K4: ='Balance Sheet'!R4 -> 527854 | L4: ='Balance Sheet'!X4 -> 164917 | M4: ='Balance Sheet'!AL4 -> 201875 | N4: 3182 | O4: 75639 | P4: 12109 | Q4: 75823 | R4: =SUM(O4:Q4) -> 163571 | S4: 48663 | T4: =-'Cash Flow'!F4 -> 52729 | U4: =(C4-C5)/C5 -> 0.11829574 | V4: =D4/C4 -> 0.46982089 | W4: =E4/C4 -> 0.14877737 | X4: =F4/C4 -> 0.064114408 | Y4: =G4/C4 -> 0.065340954 | Z4: =(G4-H4)/G4 -> 0.18989802 | AA4: =H4/C4 -> 0.052932836 | AB4: =H4/M4 -> 0.15071207 | AC4: =(F4*(1-Z4))/(Q4-I4+M4) -> 0.15637016 | AD4: =H4/K4 -> 0.057639044 | AE4: =(I4+'Balance Sheet'!E4)/L4 -> 0.80729094 | AF4: =J4/L4 -> 1.0450772 | AG4: =Q4-I4 -> -10957 | AH4: =Q4/M4 -> 0.37559381 | AI4: =Q4/SUM(Q4,M4) -> 0.27304122 | AJ4: =Q4/K4 -> 0.14364389 | AK4: =F4/N4 -> 11.581395 | AL4: =K4/M4 -> 2.6147567 | AM4: =T4/C4 -> 0.09173691 | AN4: ='Balance Sheet'!J4/Ratios!K4 -> 0.75172491 | AO4: ='Cash Flow'!E4/C4 -> 0.14778743 | AP4: =('Cash Flow'!E4+'Cash Flow'!F4)/Ratios!C4 -> 0.056050523 | AQ4: 19.44
A5: AMZN | B5: 44926 | C5: ='Income Statement'!C5 -> 513983 | D5: ='Income Statement'!E5 -> 225152 | E5: 38852 | F5: ='Income Statement'!L5 -> 12248 | G5: ='Income Statement'!P5 -> -5936 | H5: ='Income Statement'!R5 -> -2722 | I5: ='Balance Sheet'!D5 -> 70026 | J5: ='Balance Sheet'!I5 -> 146791 | K5: ='Balance Sheet'!R5 -> 462675 | L5: ='Balance Sheet'!X5 -> 155393 | M5: ='Balance Sheet'!AL5 -> 146043 | N5: 2367 | O5: 69040 | P5: 15783 | Q5: 76949 | R5: =SUM(O5:Q5) -> 161772 | S5: 41921 | T5: =-'Cash Flow'!F5 -> 63645 | U5: =(C5-C6)/C6 -> 0.093995173 | V5: =D5/C5 -> 0.4380534 | W5: =E5/C5 -> 0.075590049 | X5: =F5/C5 -> 0.023829582 | Y5: =G5/C5 -> -0.01154902 | Z5: =(G5-H5)/G5 -> 0.54144205 | AA5: =H5/C5 -> -0.005295895 | AB5: =H5/M5 -> -0.018638346 | AC5: =(F5*(1-Z5))/(Q5-I5+M5) -> 0.036716772 | AD5: =H5/K5 -> -0.0058831793 | AE5: =(I5+'Balance Sheet'!E5)/L5 -> 0.72093338 | AF5: =J5/L5 -> 0.94464358 | AG5: =Q5-I5 -> 6923 | AH5: =Q5/M5 -> 0.52689276 | AI5: =Q5/SUM(Q5,M5) -> 0.34507516 | AJ5: =Q5/K5 -> 0.16631329 | AK5: =F5/N5 -> 5.1744825 | AL5: =K5/M5 -> 3.1680738 | AM5: =T5/C5 -> 0.12382705 | AN5: ='Balance Sheet'!J5/Ratios!K5 -> 0.75615281 | AO5: ='Cash Flow'!E5/C5 -> 0.090960207 | AP5: =('Cash Flow'!E5+'Cash Flow'!F5)/Ratios!C5 -> -0.032866846 | AQ5: 14.26
A6: AMZN | B6: 44561 | C6: ='Income Statement'!C6 -> 469822 | D6: ='Income Statement'!E6 -> 197478 | E6: 48291 | F6: ='Income Statement'!L6 -> 24879 | G6: ='Income Statement'!P6 -> 38151 | H6: ='Income Statement'!R6 -> 33364 | I6: ='Balance Sheet'!D6 -> 96049 | J6: ='Balance Sheet'!I6 -> 161580 | K6: ='Balance Sheet'!R6 -> 420549 | L6: ='Balance Sheet'!X6 -> 142266 | M6: ='Balance Sheet'!AL6 -> 138245 | N6: 1809 | O6: 58330 | P6: 23753 | Q6: 52769 | R6: =SUM(O6:Q6) -> 134852 | S6: 34433 | T6: =-'Cash Flow'!F6 -> 61053 | U6: =(C6-C7)/C7 -> 0.21695367 | V6: =D6/C6 -> 0.42032514 | W6: =E6/C6 -> 0.10278574 | X6: =F6/C6 -> 0.052954098 | Y6: =G6/C6 -> 0.081203094 | Z6: =(G6-H6)/G6 -> 0.12547509 | AA6: =H6/C6 -> 0.071014129 | AB6: =H6/M6 -> 0.24133965 | AC6: =(F6*(1-Z6))/(Q6-I6+M6) -> 0.22910868 | AD6: =H6/K6 -> 0.079334394 | AE6: =(I6+'Balance Sheet'!E6)/L6 -> 0.90462936 | AF6: =J6/L6 -> 1.1357598 | AG6: =Q6-I6 -> -43280 | AH6: =Q6/M6 -> 0.38170639 | AI6: =Q6/SUM(Q6,M6) -> 0.27625724 | AJ6: =Q6/K6 -> 0.12547646 | AK6: =F6/N6 -> 13.752902 | AL6: =K6/M6 -> 3.0420558 | AM6: =T6/C6 -> 0.12994921 | AN6: ='Balance Sheet'!J6/Ratios!K6 -> 0.70118345 | AO6: ='Cash Flow'!E6/C6 -> 0.098605429 | AP6: =('Cash Flow'!E6+'Cash Flow'!F6)/Ratios!C6 -> -0.031343786 | AQ6: 13.58
A7: AMZN | B7: 44196 | C7: ='Income Statement'!C7 -> 386064 | D7: ='Income Statement'!E7 -> 152757 | E7: 51108 | F7: ='Income Statement'!L7 -> 22899 | G7: ='Income Statement'!P7 -> 24178 | H7: ='Income Statement'!R7 -> 21331 | I7: ='Balance Sheet'!D7 -> 84396 | J7: ='Balance Sheet'!I7 -> 132733 | K7: ='Balance Sheet'!R7 -> 321195 | L7: ='Balance Sheet'!X7 -> 126385 | M7: ='Balance Sheet'!AL7 -> 93404 | N7: 1647 | O7: 39099 | P7: 28434 | Q7: 33696 | R7: =SUM(O7:Q7) -> 101229 | S7: 25180 | T7: =-'Cash Flow'!F7 -> 40140 | U7: =(C7-C8)/C8 -> 0.37623431 | V7: =D7/C7 -> 0.39567792 | W7: =E7/C7 -> 0.1323822 | X7: =F7/C7 -> 0.059314 | Y7: =G7/C7 -> 0.062626922 | Z7: =(G7-H7)/G7 -> 0.11775168 | AA7: =H7/C7 -> 0.055252497 | AB7: =H7/M7 -> 0.22837352 | AC7: =(F7*(1-Z7))/(Q7-I7+M7) -> 0.47308459 | AD7: =H7/K7 -> 0.06641137 | AE7: =(I7+'Balance Sheet'!E7)/L7 -> 0.86010998 | AF7: =J7/L7 -> 1.0502275 | AG7: =Q7-I7 -> -50700 | AH7: =Q7/M7 -> 0.36075543 | AI7: =Q7/SUM(Q7,M7) -> 0.26511408 | AJ7: =Q7/K7 -> 0.10490823 | AK7: =F7/N7 -> 13.903461 | AL7: =K7/M7 -> 3.4387714 | AM7: =T7/C7 -> 0.1039724 | AN7: ='Balance Sheet'!J7/Ratios!K7 -> 0.65723626 | AO7: ='Cash Flow'!E7/C7 -> 0.17112189 | AP7: =('Cash Flow'!E7+'Cash Flow'!F7)/Ratios!C7 -> 0.067149488 | AQ7: 9.28
A8: AMZN | B8: 43830 | C8: ='Income Statement'!C8 -> 280522 | D8: ='Income Statement'!E8 -> 114986 | E8: 30256 | F8: ='Income Statement'!L8 -> 14541 | G8: ='Income Statement'!P8 -> 13976 | H8: ='Income Statement'!R8 -> 11588 | I8: ='Balance Sheet'!D8 -> 55021 | J8: ='Balance Sheet'!I8 -> 96334 | K8: ='Balance Sheet'!R8 -> 225248 | L8: ='Balance Sheet'!X8 -> 87812 | M8: ='Balance Sheet'!AL8 -> 62060 | N8: 1600 | O8: 25835 | P8: 26979 | Q8: 26127 | R8: =SUM(O8:Q8) -> 78941 | S8: 21789 | T8: =-'Cash Flow'!F8 -> 16861 | U8: =(C8-C9)/C9 -> 0.20454126 | V8: =D8/C8 -> 0.40990011 | W8: =E8/C8 -> 0.10785607 | X8: =F8/C8 -> 0.051835507 | Y8: =G8/C8 -> 0.049821404 | Z8: =(G8-H8)/G8 -> 0.17086434 | AA8: =H8/C8 -> 0.041308703 | AB8: =H8/M8 -> 0.18672253 | AC8: =(F8*(1-Z8))/(Q8-I8+M8) -> 0.36351871 | AD8: =H8/K8 -> 0.051445518 | AE8: =(I8+'Balance Sheet'!E8)/L8 -> 0.86048604 | AF8: =J8/L8 -> 1.0970482 | AG8: =Q8-I8 -> -28894 | AH8: =Q8/M8 -> 0.42099581 | AI8: =Q8/SUM(Q8,M8) -> 0.29626816 | AJ8: =Q8/K8 -> 0.11599215 | AK8: =F8/N8 -> 9.088125 | AL8: =K8/M8 -> 3.6295198 | AM8: =T8/C8 -> 0.060105803 | AN8: ='Balance Sheet'!J8/Ratios!K8 -> 0.64294023 | AO8: ='Cash Flow'!E8/C8 -> 0.13729404 | AP8: =('Cash Flow'!E8+'Cash Flow'!F8)/Ratios!C8 -> 0.077188242 | AQ8: 6.23
A9: AMZN | B9: 43465 | C9: ='Income Statement'!C9 -> 232887 | D9: ='Income Statement'!E9 -> 93731 | E9: 25034 | F9: ='Income Statement'!L9 -> 12421 | G9: ='Income Statement'!P9 -> 11261 | H9: ='Income Statement'!R9 -> 10073 | I9: ='Balance Sheet'!D9 -> 41250 | J9: ='Balance Sheet'!I9 -> 75101 | K9: ='Balance Sheet'!R9 -> 162648 | L9: ='Balance Sheet'!X9 -> 68391 | M9: ='Balance Sheet'!AL9 -> 43549 | N9: 1417 | O9: 26666 | P9: =17370+7053 -> 24423 | Q9: 26336 | R9: =SUM(O9:Q9) -> 77425 | S9: 15341 | T9: =-'Cash Flow'!F9 -> 13427 | U9: =(C9-C10)/C10 -> 0.30933962 | V9: =D9/C9 -> 0.40247416 | W9: =E9/C9 -> 0.10749419 | X9: =F9/C9 -> 0.053334879 | Y9: =G9/C9 -> 0.048353923 | Z9: =(G9-H9)/G9 -> 0.10549685 | AA9: =H9/C9 -> 0.043252736 | AB9: =H9/M9 -> 0.23130267 | AC9: =(F9*(1-Z9))/(Q9-I9+M9) -> 0.38800851 | AD9: =H9/K9 -> 0.061931287 | AE9: =(I9+'Balance Sheet'!E9)/L9 -> 0.84699741 | AF9: =J9/L9 -> 1.0981123 | AG9: =Q9-I9 -> -14914 | AH9: =Q9/M9 -> 0.60474408 | AI9: =Q9/SUM(Q9,M9) -> 0.37684768 | AJ9: =Q9/K9 -> 0.16192022 | AK9: =F9/N9 -> 8.7657022 | AL9: =K9/M9 -> 3.7348274 | AM9: =T9/C9 -> 0.057654571 | AN9: ='Balance Sheet'!J9/Ratios!K9 -> 0.58881757 | AO9: ='Cash Flow'!E9/C9 -> 0.13192235 | AP9: =('Cash Flow'!E9+'Cash Flow'!F9)/Ratios!C9 -> 0.074267778 | AQ9: 4.43
A10: AMZN | B10: 43100 | C10: ='Income Statement'!C10 -> 177866 | D10: ='Income Statement'!E10 -> 65932 | E10: 13272 | F10: ='Income Statement'!L10 -> 4106 | G10: ='Income Statement'!P10 -> 3806 | H10: ='Income Statement'!R10 -> 3033 | I10: ='Balance Sheet'!D10 -> 30986 | J10: ='Balance Sheet'!I10 -> 60197 | K10: ='Balance Sheet'!R10 -> 131310 | L10: ='Balance Sheet'!X10 -> 57883 | M10: ='Balance Sheet'!AL10 -> 27709 | N10: 848 | O10: 22848 | P10: =14277+5027 -> 19304 | Q10: 9894 | R10: =SUM(O10:Q10) -> 52046 | S10: 11478 | T10: =-'Cash Flow'!F10 -> 11955 | U10: =(C10-C11)/C11 -> 0.30796326 | V10: =D10/C10 -> 0.37068355 | W10: =E10/C10 -> 0.074617971 | X10: =F10/C10 -> 0.023084794 | Y10: =G10/C10 -> 0.021398131 | Z10: =(G10-H10)/G10 -> 0.20310037 | AA10: =H10/C10 -> 0.017052163 | AB10: =H10/M10 -> 0.10945902 | AC10: =(F10*(1-Z10))/(Q10-I10+M10) -> 0.49449447 | AD10: =H10/K10 -> 0.023098012 | AE10: =(I10+'Balance Sheet'!E10)/L10 -> 0.76274554 | AF10: =J10/L10 -> 1.0399772 | AG10: =Q10-I10 -> -21092 | AH10: =Q10/M10 -> 0.3570681 | AI10: =Q10/SUM(Q10,M10) -> 0.2631173 | AJ10: =Q10/K10 -> 0.075348412 | AK10: =F10/N10 -> 4.8419811 | AL10: =K10/M10 -> 4.7388935 | AM10: =T10/C10 -> 0.06721352 | AN10: ='Balance Sheet'!J10/Ratios!K10 -> 0.52222222 | AO10: ='Cash Flow'!E10/C10 -> 0.10325189 | AP10: =('Cash Flow'!E10+'Cash Flow'!F10)/Ratios!C10 -> 0.036038366 | AQ10: 2.86
A11: AMZN | B11: 42735 | C11: ='Income Statement'!C11 -> 135987 | D11: ='Income Statement'!E11 -> 47722 | E11: 10873 | F11: ='Income Statement'!L11 -> 4186 | G11: ='Income Statement'!P11 -> 3892 | H11: ='Income Statement'!R11 -> 2371 | I11: ='Balance Sheet'!D11 -> 25981 | J11: ='Balance Sheet'!I11 -> 45781 | K11: ='Balance Sheet'!R11 -> 83402 | L11: ='Balance Sheet'!X11 -> 43816 | M11: ='Balance Sheet'!AL11 -> 19285 | N11: 484 | O11: 9510 | P11: 11660 | Q11: 8800 | R11: =SUM(O11:Q11) -> 29970 | S11: 8116 | T11: =-'Cash Flow'!F11 -> 7804 | U11: =(C11-C12)/C12 -> 0.27083528 | V11: =D11/C11 -> 0.3509306 | W11: =E11/C11 -> 0.079956172 | X11: =F11/C11 -> 0.030782354 | Y11: =G11/C11 -> 0.028620383 | Z11: =(G11-H11)/G11 -> 0.39080164 | AA11: =H11/C11 -> 0.01743549 | AB11: =H11/M11 -> 0.12294529 | AC11: =(F11*(1-Z11))/(Q11-I11+M11) -> 1.2120268 | AD11: =H11/K11 -> 0.028428575 | AE11: =(I11+'Balance Sheet'!E11)/L11 -> 0.78327552 | AF11: =J11/L11 -> 1.0448466 | AG11: =Q11-I11 -> -17181 | AH11: =Q11/M11 -> 0.4563132 | AI11: =Q11/SUM(Q11,M11) -> 0.31333452 | AJ11: =Q11/K11 -> 0.10551306 | AK11: =F11/N11 -> 8.6487603 | AL11: =K11/M11 -> 4.3247083 | AM11: =T11/C11 -> 0.057387839 | AN11: ='Balance Sheet'!J11/Ratios!K11 -> 0.50887269 | AO11: ='Cash Flow'!E11/C11 -> 0.12650474 | AP11: =('Cash Flow'!E11+'Cash Flow'!F11)/Ratios!C11 -> 0.069116901 | AQ11: 2.02
A12: AMZN | B12: 42369 | C12: ='Income Statement'!C12 -> 107006 | D12: ='Income Statement'!E12 -> 35355 | E12: 7361 | F12: ='Income Statement'!L12 -> 2233 | G12: ='Income Statement'!P12 -> 1568 | H12: ='Income Statement'!R12 -> 596 | I12: ='Balance Sheet'!D12 -> 19808 | J12: ='Balance Sheet'!I12 -> 35705 | K12: ='Balance Sheet'!R12 -> 64747 | L12: ='Balance Sheet'!X12 -> 33887 | M12: ='Balance Sheet'!AL12 -> 13384 | N12: 459 | O12: 6517 | P12: =7239+1835 -> 9074 | Q12: 8562 | R12: =SUM(O12:Q12) -> 24153 | S12: 6281 | T12: =-'Cash Flow'!F12 -> 4589 | U12: =(C12-C13)/C13 -> 0.20247674 | V12: =D12/C12 -> 0.33040203 | W12: =E12/C12 -> 0.068790535 | X12: =F12/C12 -> 0.020867989 | Y12: =G12/C12 -> 0.014653384 | Z12: =(G12-H12)/G12 -> 0.61989796 | AA12: =H12/C12 -> 0.0055697811 | AB12: =H12/M12 -> 0.044530783 | AC12: =(F12*(1-Z12))/(Q12-I12+M12) -> 0.39699151 | AD12: =H12/K12 -> 0.0092050597 | AE12: =(I12+'Balance Sheet'!E12)/L12 -> 0.75137959 | AF12: =J12/L12 -> 1.0536489 | AG12: =Q12-I12 -> -11246 | AH12: =Q12/M12 -> 0.63971907 | AI12: =Q12/SUM(Q12,M12) -> 0.39013943 | AJ12: =Q12/K12 -> 0.13223779 | AK12: =F12/N12 -> 4.8649237 | AL12: =K12/M12 -> 4.837642 | AM12: =T12/C12 -> 0.042885446 | AN12: ='Balance Sheet'!J12/Ratios!K12 -> 0.4641605 | AO12: ='Cash Flow'!E12/C12 -> 0.11139562 | AP12: =('Cash Flow'!E12+'Cash Flow'!F12)/Ratios!C12 -> 0.068510177 | AQ12: 1.42
A13: AMZN | B13: 42004 | C13: ='Income Statement'!C13 -> 88988 | D13: ='Income Statement'!E13 -> 26236 | E13: 3959 | F13: ='Income Statement'!L13 -> 178 | G13: ='Income Statement'!P13 -> -111 | H13: ='Income Statement'!R13 -> -241 | I13: ='Balance Sheet'!D13 -> 17416 | J13: ='Balance Sheet'!I13 -> 31327 | K13: ='Balance Sheet'!R13 -> 54505 | L13: ='Balance Sheet'!X13 -> 28089 | M13: ='Balance Sheet'!AL13 -> 10741 | N13: 210 | O13: 5913 | P13: =5039+1265 -> 6304 | Q13: 9881 | R13: =SUM(O13:Q13) -> 22098 | S13: 4746 | T13: =-'Cash Flow'!F13 -> 4893 | U13: =(C13-C14)/C14 -> 0.19523989 | V13: =D13/C13 -> 0.29482627 | W13: =E13/C13 -> 0.044489145 | X13: =F13/C13 -> 0.0020002697 | Y13: =G13/C13 -> -0.0012473592 | Z13: =(G13-H13)/G13 -> -1.1711712 | AA13: =H13/C13 -> -0.0027082303 | AB13: =H13/M13 -> -0.022437389 | AC13: =(F13*(1-Z13))/(Q13-I13+M13) -> 0.12054537 | AD13: =H13/K13 -> -0.0044216127 | AE13: =(I13+'Balance Sheet'!E13)/L13 -> 0.81982271 | AF13: =J13/L13 -> 1.1152764 | AG13: =Q13-I13 -> -7535 | AH13: =Q13/M13 -> 0.91993297 | AI13: =Q13/SUM(Q13,M13) -> 0.47914848 | AJ13: =Q13/K13 -> 0.18128612 | AK13: =F13/N13 -> 0.84761905 | AL13: =K13/M13 -> 5.074481 | AM13: =T13/C13 -> 0.054984942 | AN13: ='Balance Sheet'!J13/Ratios!K13 -> 0.41702596 | AO13: ='Cash Flow'!E13/C13 -> 0.076886771 | AP13: =('Cash Flow'!E13+'Cash Flow'!F13)/Ratios!C13 -> 0.021901829 | AQ13: 1.15
A14: AMZN | B14: 41639 | C14: ='Income Statement'!C14 -> 74452 | D14: ='Income Statement'!E14 -> 20271 | E14: 3413 | F14: ='Income Statement'!L14 -> 745 | G14: ='Income Statement'!P14 -> 506 | H14: ='Income Statement'!R14 -> 274 | I14: ='Balance Sheet'!D14 -> 12447 | J14: ='Balance Sheet'!I14 -> 24625 | K14: ='Balance Sheet'!R14 -> 40159 | L14: ='Balance Sheet'!X14 -> 22980 | M14: ='Balance Sheet'!AL14 -> 9746 | N14: 141 | O14: 5135 | P14: =2390+583 -> 2973 | Q14: 3967 | R14: 3967 | S14: 3253 | T14: =-'Cash Flow'!F14 -> 3444 | U14: =(C14-C15)/C15 -> 0.21866662 | V14: =D14/C14 -> 0.27226938 | W14: =E14/C14 -> 0.045841616 | X14: =F14/C14 -> 0.010006447 | Y14: =G14/C14 -> 0.0067963251 | Z14: =(G14-H14)/G14 -> 0.45849802 | AA14: =H14/C14 -> 0.0036802235 | AB14: =H14/M14 -> 0.028114098 | AC14: =(F14*(1-Z14))/(Q14-I14+M14) -> 0.31865638 | AD14: =H14/K14 -> 0.0068228791 | AE14: =(I14+'Balance Sheet'!E14)/L14 -> 0.74908616 | AF14: =J14/L14 -> 1.071584 | AG14: =Q14-I14 -> -8480 | AH14: =Q14/M14 -> 0.40703879 | AI14: =Q14/SUM(Q14,M14) -> 0.28928754 | AJ14: =Q14/K14 -> 0.09878234 | AK14: =F14/N14 -> 5.2836879 | AL14: =K14/M14 -> 4.1205623 | AM14: =T14/C14 -> 0.046257992 | AN14: ='Balance Sheet'!J14/Ratios!K14 -> 0.36875918 | AO14: ='Cash Flow'!E14/C14 -> 0.073537313 | AP14: =('Cash Flow'!E14+'Cash Flow'!F14)/Ratios!C14 -> 0.027279321 | AQ14: 1.06
A15: AMZN | B15: 41274 | C15: ='Income Statement'!C15 -> 61093 | D15: ='Income Statement'!E15 -> 15122 | E15: 2539 | F15: ='Income Statement'!L15 -> 676 | G15: ='Income Statement'!P15 -> 544 | H15: ='Income Statement'!R15 -> -39 | I15: ='Balance Sheet'!D15 -> 11448 | J15: ='Balance Sheet'!I15 -> 21296 | K15: ='Balance Sheet'!R15 -> 32555 | L15: ='Balance Sheet'!X15 -> 19002 | M15: ='Balance Sheet'!AL15 -> 8192 | N15: 92 | O15: 5454 | P15: 1292 | Q15: 3691 | R15: =SUM(O15:Q15) -> 10437 | S15: 2159 | T15: =-'Cash Flow'!F15 -> 3785 | U15: =(C15-C16)/C16 -> 0.27073237 | V15: =D15/C15 -> 0.24752427 | W15: =E15/C15 -> 0.041559589 | X15: =F15/C15 -> 0.011065097 | Y15: =G15/C15 -> 0.0089044571 | Z15: =(G15-H15)/G15 -> 1.0716912 | AA15: =H15/C15 -> -0.00063837101 | AB15: =H15/M15 -> -0.0047607422 | AC15: =(F15*(1-Z15))/(Q15-I15+M15) -> -0.11140974 | AD15: =H15/K15 -> -0.0011979727 | AE15: =(I15+'Balance Sheet'!E15)/L15 -> 0.7794969 | AF15: =J15/L15 -> 1.1207241 | AG15: =Q15-I15 -> -7757 | AH15: =Q15/M15 -> 0.45056152 | AI15: =Q15/SUM(Q15,M15) -> 0.3106118 | AJ15: =Q15/K15 -> 0.11337736 | AK15: =F15/N15 -> 7.3478261 | AL15: =K15/M15 -> 3.973999 | AM15: =T15/C15 -> 0.061954725 | AN15: ='Balance Sheet'!J15/Ratios!K15 -> 0.29433267 | AO15: ='Cash Flow'!E15/C15 -> 0.068420277 | AP15: =('Cash Flow'!E15+'Cash Flow'!F15)/Ratios!C15 -> 0.0064655525 | AQ15: 0.9
